Workbook

Sheet ZBC-Main Page
G1: Next
A2: Project Unnati
B4: Zero Based Costing Sheet
B6: Source
B8: Destination
B10: One - Way Distance | C10: 2224 | F10: (Km)
B12: Truck Type | C12: Canter 6.5T
B14: % Onward Load | C14: 0.8
B16: % Return Load | C16: 1
B18: Toll Charges (One-Way) | C18: 0 | F18: (Rs.)
B21: ZBC Per Ton Per Km Rate | C21: =VLOOKUP(CONCATENATE($C$12,$C$16),'Search Index'!$D$6:$G$68,2,FALSE) -> 2.2417144 | F21: (Rs./Ton/Km)
B23: ZBC Per Ton Rate | C23: =VLOOKUP(CONCATENATE($C$12,$C$16),'Search Index'!$D$6:$G$68,3,FALSE) -> 4985.5727 | F23: (Rs./Ton)
B25: ZBC Per Trip Rate | C25: =VLOOKUP(CONCATENATE($C$12,$C$16),'Search Index'!$D$6:$G$68,4,FALSE) -> 37142.517 | F25: (Rs./Trip)
D28: Data Input Required
D30: ZBC Rates

Sheet Input_Data
B1: Previous | E1: Main-Page
A2: Project Unnati
B4: Data Input Sheet
C6: Tempo 2T 3W | D6: Tempo 2T 4W | E6: Canter 4T | F6: Canter 6.5T | G6: Canter 8.5T | H6: Truck 9T | I6: Container 14T | J6: Turbo 15T | K6: Tata 0.7T
B7: Truck Type | C7: Tempo | D7: Tempo | E7: Canter | F7: Canter | G7: Canter | H7: Truck | I7: Container | J7: Turbo | K7: Tata
B8: Tonnage | C8: 2 | D8: 2 | E8: 4 | F8: 6.5 | G8: 8.5 | H8: 9 | I8: 14 | J8: 15 | K8: 0.7
B9: On road price (excluding RC) | C9: 669410 | D9: 669410 | E9: 957463 | F9: 1017000 | G9: 1215730 | H9: 1455000 | I9: 1965000 | J9: 1685000
B10: RC fitness (one time) | C10: 65000 | D10: 65000 | E10: 65000 | F10: 68000 | G10: 71000 | H10: 110000 | I10: 135000 | J10: 115000 | L10: ?
B11: Cabin & Body making expenses | C11: 38000 | D11: 38000 | E11: 38000 | F11: 40000 | G11: 45000 | H11: 45000 | I11: 300000 | J11: 150000 | L11: ?
B12: Life of truck (years) | C12: 10 | D12: 10 | E12: 10 | F12: 10 | G12: 10 | H12: 10 | I12: 10 | J12: 10
B13: Driver Salary | C13: 11500 | D13: 11500 | E13: 13000 | F13: 14500 | G13: 14500 | H13: 14500 | I13: 17000 | J13: 17000
B14: Helper Salary | C14: 0 | D14: 0 | E14: 9000 | F14: 8500 | G14: 8500 | H14: 8500 | I14: 10000 | J14: 10000
B15: Permit & Road tax per year | C15: 22000 | D15: 22000 | E15: 22000 | F15: 22000 | G15: 22000 | H15: 25000 | I15: 27000 | J15: 26000
B16: Mileage-Full load | C16: 12 | D16: 12 | E16: 10 | F16: 9 | G16: 8 | H16: 5 | I16: 3.5 | J16: 4
B17: Mileage-Empty load | C17: 11 | D17: 11 | E17: 11 | F17: 10 | G17: 10 | H17: 6 | I17: 4 | J17: 5
B18: No.of tyre (pairs) | C18: 2 | D18: 2 | E18: 2 | F18: 2 | G18: 3 | H18: 3 | I18: 5 | J18: 6
B19: Tyre life (without retreading) | C19: 50000 | D19: 50000 | E19: 50000 | F19: 45000 | G19: 45000 | H19: 38000 | I19: 40000 | J19: 40000 | L19: ?
B20: Tyre life (after 1st retreading) | C20: 30000 | D20: 30000 | E20: 30000 | F20: 25000 | G20: 25000 | H20: 18000 | I20: 20000 | J20: 20000 | L20: ?
B21: Engine oil change interval (kms) | C21: 40000 | D21: 40000 | E21: 40000 | F21: 35000 | G21: 35000 | H21: 35000 | I21: 35000 | J21: 35000 | L21: ?
B22: Gear oil change interval (kms) | C22: 80000 | D22: 80000 | E22: 80000 | F22: 75000 | G22: 75000 | H22: 75000 | I22: 75000 | J22: 75000
B23: Axle oil change interval (kms) | C23: 80000 | D23: 80000 | E23: 80000 | F23: 75000 | G23: 75000 | H23: 75000 | I23: 75000 | J23: 75000
B24: Coolant change interval (kms) | C24: 160000 | D24: 160000 | E24: 160000 | F24: 150000 | G24: 150000 | H24: 150000 | I24: 150000 | J24: 150000
B25: Engine oil change Qty (per change) | C25: 11 | D25: 11 | E25: 11 | F25: 11 | G25: 11 | H25: 11 | I25: 15 | J25: 15
B26: Gear oil change Qty (per change) | C26: 3.6 | D26: 3.6 | E26: 3.6 | F26: 5 | G26: 5 | H26: 5 | I26: 7 | J26: 7
B27: Axle oil change Qty (per change) | C27: 4.5 | D27: 4.5 | E27: 4.5 | F27: 4.5 | G27: 4.5 | H27: 4.5 | I27: 12 | J27: 12
B28: Coolant change Qty (per change) | C28: 2 | D28: 2 | E28: 5 | F28: 5 | G28: 5 | H28: 5 | I28: 5 | J28: 5
B29: Engine oil cost (per ) | C29: 285 | D29: 285 | E29: 285 | F29: 285 | G29: 285 | H29: 285 | I29: 285 | J29: 285
B30: Gear oil cost (per ) | C30: 295 | D30: 295 | E30: 295 | F30: 295 | G30: 295 | H30: 295 | I30: 295 | J30: 295
B31: Axle oil cost (per ) | C31: 285 | D31: 285 | E31: 285 | F31: 285 | G31: 285 | H31: 285 | I31: 285 | J31: 285
B32: Coolant cost (per ) | C32: 400 | D32: 400 | E32: 400 | F32: 400 | G32: 400 | H32: 400 | I32: 400 | J32: 400
B33: Fuel filter change interval (kms) | C33: 40000 | D33: 40000 | E33: 40000 | F33: 35000 | G33: 35000 | H33: 30000 | I33: 35000 | J33: 37000
... B40: Distance travelled in a year | C40: 72000 | D40: 72000 | E40: 72000 | F40: 72000 | G40: 72000 | H40: 72000 | I40: 72000 | J40: 72000
B41: Tarpaulin Laying Chanrges | C41: 1200 | D41: 1200 | E41: 1200 | F41: 1300 | G41: 1300 | H41: 1300 | I41: 0 | J41: 1400 | L41: ?
B42: RTO +Police unofficial +Toll | C42: 0 | D42: 0 | E42: 0 | F42: 0 | G42: 0 | H42: 0 | I42: 0 | J42: 0
B43: Unloading Charges | C43: 0 | D43: 0 | E43: 0 | F43: 0 | G43: 0 | H43: 0 | I43: 0 | J43: 0
B44: One way distance | C44: ='ZBC-Main Page'!$C$10:$E$10 -> 2224 | D44: =$C$44 -> 2224 | E44: =$C$44 -> 2224 | F44: =$C$44 -> 2224 | G44: =$C$44 -> 2224 | H44: =$C$44 -> 2224 | I44: =$C$44 -> 2224 | J44: =$C$44 -> 2224
B45: Net Weight | C45: 2.2 | D45: 3.87 | E45: 4 | F45: 7.45 | G45: 8.5 | H45: 10.7 | I45: 14 | J45: 15
B46: No of Batteries | C46: 1 | D46: 1 | E46: 1 | F46: 1 | G46: 1 | H46: 1 | I46: 2 | J46: 2
B50: Tarpaulin (original) | C50: 12000 | D50: 12000 | E50: 12000 | F50: 13000 | G50: 13000 | H50: 13000 | I50: 0 | J50: 14000

Sheet Guidelines
B1: Previous | C1: Main-Page | F1: Next
A2: Project Unnati
B4: Guidelines
B7: Details | C7: Value | E7: Trucks Covered
B8: Salavage Value after 5 Years (%) | C8: 0.35 | E8: Tempo 2T 3W
B9: Insurance Premium Rate | C9: 0.025 | E9: Tempo 2T 4W
B10: Vehicle Loan Amount | C10: 0.8 | E10: Canter 4T
B11: Interest Rate | C11: 0.11 | E11: Container 14T
B12: Loan Terms (years) | C12: 5 | E12: Turbo 15T
B13: Tyre Cost per Pair | C13: 40000 | E13: Tata 0.7T
B14: Retreading Cost per pair | C14: 9000 | E14: Canter 6.5T
B15: Battery Life (Kms) | C15: 100000 | E15: Canter 8.5T
B16: Battery Cost (Rs/Battery) | C16: 12000 | E16: Truck 9T
B17: Threshold distance for rest time addition (km) | C17: 150
B18: Placement to Plant (hrs) | C18: 2
B19: Plant turnaround time (hrs) | C19: 4
B20: Turnaround at Client (hrs) | C20: 4
B21: Wait Time for Pick up for return load | C21: 12
B22: Return to Garage | C22: 4
B23: Total Rest time (calculated for every 16 hrs working) | C23: 8
B24: Hours of rest for every 16 hrs of working | C24: 8
B25: Work hours considered | C25: 16
B26: # uptime per truck | C26: 0.9
B27: Overhead cost (over fixed & variable) | C27: 0.07
B28: Profit (over fixed & variable) | C28: 0.1

Sheet Master Sheet
B1: Previous | E1: Main-Page
A2: Project Unnati
B4: Depreciation Working
B5: Truck Type | C5: Rate | D5: Tempo 2T 3W | E5: Tempo 2T 4W | F5: Canter 4T | G5: Canter 6.5T | H5: Canter 8.5T | I5: Truck 9T | J5: Container 14T | K5: Turbo 15T | L5: Tata 0.7T
B6: Chassis Expenses+ Reg Charges | D6: =Input_Data!C9 -> 669410 | E6: =Input_Data!D9 -> 669410 | F6: =Input_Data!E9 -> 957463 | G6: =Input_Data!F9 -> 1017000 | H6: =Input_Data!G9 -> 1215730 | I6: =Input_Data!H9 -> 1455000 | J6: =Input_Data!I9 -> 1965000 | K6: =Input_Data!J9 -> 1685000 | L6: =Input_Data!K9 -> 0
B7: RC fitness (one time) | D7: =Input_Data!C10 -> 65000 | E7: =Input_Data!D10 -> 65000 | F7: =Input_Data!E10 -> 65000 | G7: =Input_Data!F10 -> 68000 | H7: =Input_Data!G10 -> 71000 | I7: =Input_Data!H10 -> 110000 | J7: =Input_Data!I10 -> 135000 | K7: =Input_Data!J10 -> 115000 | L7: =Input_Data!K10 -> 0
B8: Cabin & Body making expenses | D8: =Input_Data!C11 -> 38000 | E8: =Input_Data!D11 -> 38000 | F8: =Input_Data!E11 -> 38000 | G8: =Input_Data!F11 -> 40000 | H8: =Input_Data!G11 -> 45000 | I8: =Input_Data!H11 -> 45000 | J8: =Input_Data!I11 -> 300000 | K8: =Input_Data!J11 -> 150000 | L8: =Input_Data!K11 -> 0
B9: Landed Cost | D9: =SUM(D6:D8) -> 772410 | E9: =SUM(E6:E8) -> 772410 | F9: =SUM(F6:F8) -> 1060463 | G9: =SUM(G6:G8) -> 1125000 | H9: =SUM(H6:H8) -> 1331730 | I9: =SUM(I6:I8) -> 1610000 | J9: =SUM(J6:J8) -> 2400000 | K9: =SUM(K6:K8) -> 1950000 | L9: =SUM(L6:L8) -> 0
B10: Salvage Value | C10: =Guidelines!$C$8 -> 0.35 | D10: =$C10*D9 -> 270343.5 | E10: =$C10*E9 -> 270343.5 | F10: =$C10*F9 -> 371162.05 | G10: =$C10*G9 -> 393750 | H10: =$C10*H9 -> 466105.5 | I10: =$C10*I9 -> 563500 | J10: =$C10*J9 -> 840000 | K10: =$C10*K9 -> 682500 | L10: =$C10*L9 -> 0
B11: Depreciation per year | D11: =(D9-D10)/5/2 -> 50206.65 | E11: =(E9-E10)/5/2 -> 50206.65 | F11: =(F9-F10)/5/2 -> 68930.095 | G11: =(G9-G10)/5/2 -> 73125 | H11: =(H9-H10)/5/2 -> 86562.45 | I11: =(I9-I10)/5/2 -> 104650 | J11: =(J9-J10)/5/2 -> 156000 | K11: =(K9-K10)/5/2 -> 126750 | L11: =(L9-L10)/5/2 -> 0
B14: Crew Salary Working
B15: Truck Type | C15: Rate | D15: Tempo 2T 3W | E15: Tempo 2T 4W | F15: Canter 4T | G15: Canter 6.5T | H15: Canter 8.5T | I15: Truck 9T | J15: Container 14T | K15: Turbo 15T | L15: Tata 0.7T
B16: Driver | D16: =Input_Data!C13 -> 11500 | E16: =Input_Data!D13 -> 11500 | F16: =Input_Data!E13 -> 13000 | G16: =Input_Data!F13 -> 14500 | H16: =Input_Data!G13 -> 14500 | I16: =Input_Data!H13 -> 14500 | J16: =Input_Data!I13 -> 17000 | K16: =Input_Data!J13 -> 17000 | L16: =Input_Data!K13 -> 0
B17: Helper | D17: =Input_Data!C14 -> 0 | E17: =Input_Data!D14 -> 0 | F17: =Input_Data!E14 -> 9000 | G17: =Input_Data!F14 -> 8500 | H17: =Input_Data!G14 -> 8500 | I17: =Input_Data!H14 -> 8500 | J17: =Input_Data!I14 -> 10000 | K17: =Input_Data!J14 -> 10000 | L17: =Input_Data!K14 -> 0
B18: Crew Salary PM | D18: =SUM(D16:D17) -> 11500 | E18: =SUM(E16:E17) -> 11500 | F18: =SUM(F16:F17) -> 22000 | G18: =SUM(G16:G17) -> 23000 | H18: =SUM(H16:H17) -> 23000 | I18: =SUM(I16:I17) -> 23000 | J18: =SUM(J16:J17) -> 27000 | K18: =SUM(K16:K17) -> 27000 | L18: =SUM(L16:L17) -> 0
B19: Crew Salary PA | D19: =D18*12 -> 138000 | E19: =E18*12 -> 138000 | F19: =F18*12 -> 264000 | G19: =G18*12 -> 276000 | H19: =H18*12 -> 276000 | I19: =I18*12 -> 276000 | J19: =J18*12 -> 324000 | K19: =K18*12 -> 324000 | L19: =L18*12 -> 0
B22: Insurance Working
B23: Truck Type | C23: Rate | D23: Tempo 2T 3W | E23: Tempo 2T 4W | F23: Canter 4T | G23: Canter 6.5T | H23: Canter 8.5T | I23: Truck 9T | J23: Container 14T | K23: Turbo 15T | L23: Tata 0.7T
B24: Initial Asset Cost | D24: =D9 -> 772410 | E24: =E9 -> 772410 | F24: =F9 -> 1060463 | G24: =G9 -> 1125000 | H24: =H9 -> 1331730 | I24: =I9 -> 1610000 | J24: =J9 -> 2400000 | K24: =K9 -> 1950000 | L24: =L9 -> 0
B25: Insurace Cost Per Year | D25: =(D27+D29+D31+D33+D35)/5 -> 15544.751 | E25: =(E27+E29+E31+E33+E35)/5 -> 15544.751 | F25: =(F27+F29+F31+F33+F35)/5 -> 21341.818 | G25: =(G27+G29+G31+G33+G35)/5 -> 22640.625 | H25: =(H27+H29+H31+H33+H35)/5 -> 26801.066 | I25: =(I27+I29+I31+I33+I35)/5 -> 32401.25 | J25: =(J27+J29+J31+J33+J35)/5 -> 48300 | K25: =(K27+K29+K31+K33+K35)/5 -> 39243.75 | L25: =(L27+L29+L31+L33+L35)/5 -> 0
B26: IDV Value 1st year | D26: =D24-D$11 -> 722203.35 | E26: =E24-E$11 -> 722203.35 | F26: =F24-F$11 -> 991532.91 | G26: =G24-G$11 -> 1051875 | H26: =H24-H$11 -> 1245167.6 | I26: =I24-I$11 -> 1505350 | J26: =J24-J$11 -> 2244000 | K26: =K24-K$11 -> 1823250 | L26: =L24-L$11 -> 0
B27: Premium Value 1st Year | C27: =Guidelines!$C$9 -> 0.025 | D27: =D26*$C27 -> 18055.084 | E27: =E26*$C27 -> 18055.084 | F27: =F26*$C27 -> 24788.323 | G27: =G26*$C27 -> 26296.875 | H27: =H26*$C27 -> 31129.189 | I27: =I26*$C27 -> 37633.75 | J27: =J26*$C27 -> 56100 | K27: =K26*$C27 -> 45581.25 | L27: =L26*$C27 -> 0
B28: IDV Value 2nd year | D28: =D26-D$11 -> 671996.7 | E28: =E26-E$11 -> 671996.7 | F28: =F26-F$11 -> 922602.81 | G28: =G26-G$11 -> 978750 | H28: =H26-H$11 -> 1158605.1 | I28: =I26-I$11 -> 1400700 | J28: =J26-J$11 -> 2088000 | K28: =K26-K$11 -> 1696500 | L28: =L26-L$11 -> 0
B29: Premium Value 2nd Year | C29: =Guidelines!$C$9 -> 0.025 | D29: =D28*$C29 -> 16799.917 | E29: =E28*$C29 -> 16799.917 | F29: =F28*$C29 -> 23065.07 | G29: =G28*$C29 -> 24468.75 | H29: =H28*$C29 -> 28965.128 | I29: =I28*$C29 -> 35017.5 | J29: =J28*$C29 -> 52200 | K29: =K28*$C29 -> 42412.5 | L29: =L28*$C29 -> 0
B30: IDV Value 3rd year | D30: =D28-D$11 -> 621790.05 | E30: =E28-E$11 -> 621790.05 | F30: =F28-F$11 -> 853672.72 | G30: =G28-G$11 -> 905625 | H30: =H28-H$11 -> 1072042.7 | I30: =I28-I$11 -> 1296050 | J30: =J28-J$11 -> 1932000 | K30: =K28-K$11 -> 1569750 | L30: =L28-L$11 -> 0
B31: Premium Value 3rd Year | C31: =Guidelines!$C$9 -> 0.025 | D31: =D30*$C31 -> 15544.751 | E31: =E30*$C31 -> 15544.751 | F31: =F30*$C31 -> 21341.818 | G31: =G30*$C31 -> 22640.625 | H31: =H30*$C31 -> 26801.066 | I31: =I30*$C31 -> 32401.25 | J31: =J30*$C31 -> 48300 | K31: =K30*$C31 -> 39243.75 | L31: =L30*$C31 -> 0
B32: IDV Value 4th year | D32: =D30-D$11 -> 571583.4 | E32: =E30-E$11 -> 571583.4 | F32: =F30-F$11 -> 784742.62 | G32: =G30-G$11 -> 832500 | H32: =H30-H$11 -> 985480.2 | I32: =I30-I$11 -> 1191400 | J32: =J30-J$11 -> 1776000 | K32: =K30-K$11 -> 1443000 | L32: =L30-L$11 -> 0
B33: Premium Value 4th Year | C33: =Guidelines!$C$9 -> 0.025 | D33: =D32*$C33 -> 14289.585 | E33: =E32*$C33 -> 14289.585 | F33: =F32*$C33 -> 19618.566 | G33: =G32*$C33 -> 20812.5 | H33: =H32*$C33 -> 24637.005 | I33: =I32*$C33 -> 29785 | J33: =J32*$C33 -> 44400 | K33: =K32*$C33 -> 36075 | L33: =L32*$C33 -> 0
B34: IDV Value 5th year | D34: =D32-D$11 -> 521376.75 | E34: =E32-E$11 -> 521376.75 | F34: =F32-F$11 -> 715812.53 | G34: =G32-G$11 -> 759375 | H34: =H32-H$11 -> 898917.75 | I34: =I32-I$11 -> 1086750 | J34: =J32-J$11 -> 1620000 | K34: =K32-K$11 -> 1316250 | L34: =L32-L$11 -> 0
B35: Premium Value 5th Year | C35: =Guidelines!$C$9 -> 0.025 | D35: =D34*$C35 -> 13034.419 | E35: =E34*$C35 -> 13034.419 | F35: =F34*$C35 -> 17895.313 | G35: =G34*$C35 -> 18984.375 | H35: =H34*$C35 -> 22472.944 | I35: =I34*$C35 -> 27168.75 | J35: =J34*$C35 -> 40500 | K35: =K34*$C35 -> 32906.25 | L35: =L34*$C35 -> 0
B38: Interest Working
B39: Truck Type | C39: Rate | D39: Tempo 2T 3W | E39: Tempo 2T 4W | F39: Canter 4T | G39: Canter 6.5T | H39: Canter 8.5T | I39: Truck 9T | J39: Container 14T | K39: Turbo 15T | L39: Tata 0.7T
B40: Loan Amount | C40: =Guidelines!$C$10 -> 0.8 | D40: =D9*$C40 -> 617928 | E40: =E9*$C40 -> 617928 | F40: =F9*$C40 -> 848370.4 | G40: =G9*$C40 -> 900000 | H40: =H9*$C40 -> 1065384 | I40: =I9*$C40 -> 1288000 | J40: =J9*$C40 -> 1920000 | K40: =K9*$C40 -> 1560000 | L40: =L9*$C40 -> 0
B41: Interest Rate | C41: =Guidelines!$C$11 -> 0.11
B42: Loan Terms (years) | C42: =Guidelines!C12 -> 5
B43: Monthly EMI | D43: =PMT($C41/12,$C42*12,-D40) -> 13435.252 | E43: =PMT($C41/12,$C42*12,-E40) -> 13435.252 | F43: =PMT($C41/12,$C42*12,-F40) -> 18445.628 | G43: =PMT($C41/12,$C42*12,-G40) -> 19568.181 | H43: =PMT($C41/12,$C42*12,-H40) -> 23164.03 | I43: =PMT($C41/12,$C42*12,-I40) -> 28004.241 | J43: =PMT($C41/12,$C42*12,-J40) -> 41745.452 | K43: =PMT($C41/12,$C42*12,-K40) -> 33918.18 | L43: =PMT($C41/12,$C42*12,-L40) -> 0
B44: Interest Cost Per Month | D44: =D111/12 -> 3136.452 | E44: =E111/12 -> 3136.452 | F44: =F111/12 -> 4306.1215 | G44: =G111/12 -> 4568.1808 | H44: =H111/12 -> 5407.6297 | I44: =I111/12 -> 6537.5743 | J44: =J111/12 -> 9745.4523 | K44: =K111/12 -> 7918.18 | L44: =L111/12 -> 0
B45: Interest Month 1 | C45: 1 | D45: =D$40*$C$41/12 -> 5664.34 | E45: =E$40*$C$41/12 -> 5664.34 | F45: =F$40*$C$41/12 -> 7776.7287 | G45: =G$40*$C$41/12 -> 8250 | H45: =H$40*$C$41/12 -> 9766.02 | I45: =I$40*$C$41/12 -> 11806.667 | J45: =J$40*$C$41/12 -> 17600 | K45: =K$40*$C$41/12 -> 14300 | L45: =L$40*$C$41/12 -> 0
B46: Interest Month 2 | C46: 2 | D46: =IF((D$40-(D$43-D45))<0,0,(D$40-(D$43-D45))*$C$41/12) -> 5593.1066 | E46: =IF((E$40-(E$43-E45))<0,0,(E$40-(E$43-E45))*$C$41/12) -> 5593.1066 | F46: =IF((F$40-(F$43-F45))<0,0,(F$40-(F$43-F45))*$C$41/12) -> 7678.9304 | G46: =IF((G$40-(G$43-G45))<0,0,(G$40-(G$43-G45))*$C$41/12) -> 8146.25 | H46: =IF((H$40-(H$43-H45))<0,0,(H$40-(H$43-H45))*$C$41/12) -> 9643.2049 | I46: =IF((I$40-(I$43-I45))<0,0,(I$40-(I$43-I45))*$C$41/12) -> 11658.189 | J46: =IF((J$40-(J$43-J45))<0,0,(J$40-(J$43-J45))*$C$41/12) -> 17378.667 | K46: =IF((K$40-(K$43-K45))<0,0,(K$40-(K$43-K45))*$C$41/12) -> 14120.167 | L46: =IF((L$40-(L$43-L45))<0,0,(L$40-(L$43-L45))*$C$41/12) -> 0
B47: Interest Month 3 | C47: 3 | D47: =IF((D$40-($C46*D$43-SUM(D$45:D46)))<0,0,(D$40-($C46*D$43-SUM(D$45:D46))))*$C$41/12 -> 5521.2203 | E47: =IF((E$40-($C46*E$43-SUM(E$45:E46)))<0,0,(E$40-($C46*E$43-SUM(E$45:E46))))*$C$41/12 -> 5521.2203 | F47: =IF((F$40-($C46*F$43-SUM(F$45:F46)))<0,0,(F$40-($C46*F$43-SUM(F$45:F46))))*$C$41/12 -> 7580.2357 | G47: =IF((G$40-($C46*G$43-SUM(G$45:G46)))<0,0,(G$40-($C46*G$43-SUM(G$45:G46))))*$C$41/12 -> 8041.549 | H47: =IF((H$40-($C46*H$43-SUM(H$45:H46)))<0,0,(H$40-($C46*H$43-SUM(H$45:H46))))*$C$41/12 -> 9519.264 | I47: =IF((I$40-($C46*I$43-SUM(I$45:I46)))<0,0,(I$40-($C46*I$43-SUM(I$45:I46))))*$C$41/12 -> 11508.35 | J47: =IF((J$40-($C46*J$43-SUM(J$45:J46)))<0,0,(J$40-($C46*J$43-SUM(J$45:J46))))*$C$41/12 -> 17155.304 | K47: =IF((K$40-($C46*K$43-SUM(K$45:K46)))<0,0,(K$40-($C46*K$43-SUM(K$45:K46))))*$C$41/12 -> 13938.685 | L47: =IF((L$40-($C46*L$43-SUM(L$45:L46)))<0,0,(L$40-($C46*L$43-SUM(L$45:L46))))*$C$41/12 -> 0
...

Sheet ZBC-Calculations
B1: Previous | E1: Main-Page
A2: Project Unnati
B4: Fixed Cost Per km
B5: Truck Type | C5: Rate | D5: Tempo 2T 3W | E5: Tempo 2T 4W | F5: Canter 4T | G5: Canter 6.5T | H5: Canter 8.5T | I5: Truck 9T | J5: Container 14T | K5: Turbo 15T | L5: Tata 0.7T
B6: Total fixed costs per Km | D6: =D12/Input_Data!C40 -> 3.6581781 | E6: =E12/Input_Data!D40 -> 3.6581781 | F6: =F12/Input_Data!E40 -> 5.9436857 | G6: =G12/Input_Data!F40 -> 6.2303305 | H6: =H12/Input_Data!G40 -> 6.6146538 | I6: =I12/Input_Data!H40 -> 7.1736408 | J6: =J12/Input_Data!I40 -> 9.336742 | K6: =K12/Input_Data!J40 -> 8.4862765 | L6: =L12/Input_Data!K40 -> #DIV/0!
B7: Depreciation of truck per year | D7: ='Master Sheet'!D11 -> 50206.65 | E7: ='Master Sheet'!E11 -> 50206.65 | F7: ='Master Sheet'!F11 -> 68930.095 | G7: ='Master Sheet'!G11 -> 73125 | H7: ='Master Sheet'!H11 -> 86562.45 | I7: ='Master Sheet'!I11 -> 104650 | J7: ='Master Sheet'!J11 -> 156000 | K7: ='Master Sheet'!K11 -> 126750 | L7: ='Master Sheet'!L11 -> 0
B8: Crew Salary per year | D8: ='Master Sheet'!D19 -> 138000 | E8: ='Master Sheet'!E19 -> 138000 | F8: ='Master Sheet'!F19 -> 264000 | G8: ='Master Sheet'!G19 -> 276000 | H8: ='Master Sheet'!H19 -> 276000 | I8: ='Master Sheet'!I19 -> 276000 | J8: ='Master Sheet'!J19 -> 324000 | K8: ='Master Sheet'!K19 -> 324000 | L8: ='Master Sheet'!L19 -> 0
B9: Insurance per year | D9: ='Master Sheet'!D25 -> 15544.751 | E9: ='Master Sheet'!E25 -> 15544.751 | F9: ='Master Sheet'!F25 -> 21341.818 | G9: ='Master Sheet'!G25 -> 22640.625 | H9: ='Master Sheet'!H25 -> 26801.066 | I9: ='Master Sheet'!I25 -> 32401.25 | J9: ='Master Sheet'!J25 -> 48300 | K9: ='Master Sheet'!K25 -> 39243.75 | L9: ='Master Sheet'!L25 -> 0
B10: Permit & Road tax per year | D10: =Input_Data!C15 -> 22000 | E10: =Input_Data!D15 -> 22000 | F10: =Input_Data!E15 -> 22000 | G10: =Input_Data!F15 -> 22000 | H10: =Input_Data!G15 -> 22000 | I10: =Input_Data!H15 -> 25000 | J10: =Input_Data!I15 -> 27000 | K10: =Input_Data!J15 -> 26000 | L10: =Input_Data!K15 -> 0
B11: Interest costs at 11% per year | D11: ='Master Sheet'!D44*12 -> 37637.424 | E11: ='Master Sheet'!E44*12 -> 37637.424 | F11: ='Master Sheet'!F44*12 -> 51673.458 | G11: ='Master Sheet'!G44*12 -> 54818.169 | H11: ='Master Sheet'!H44*12 -> 64891.556 | I11: ='Master Sheet'!I44*12 -> 78450.891 | J11: ='Master Sheet'!J44*12 -> 116945.43 | K11: ='Master Sheet'!K44*12 -> 95018.16 | L11: ='Master Sheet'!L44*12 -> 0
B12: Total fixed costs per year | D12: =SUM(D7:D11) -> 263388.83 | E12: =SUM(E7:E11) -> 263388.83 | F12: =SUM(F7:F11) -> 427945.37 | G12: =SUM(G7:G11) -> 448583.79 | H12: =SUM(H7:H11) -> 476255.07 | I12: =SUM(I7:I11) -> 516502.14 | J12: =SUM(J7:J11) -> 672245.43 | K12: =SUM(K7:K11) -> 611011.91 | L12: =SUM(L7:L11) -> 0
B15: Fuel Cost Per km
B16: Truck Type | D16: Tempo 2T 3W | E16: Tempo 2T 4W | F16: Canter 4T | G16: Canter 6.5T | H16: Canter 8.5T | I16: Truck 9T | J16: Container 14T | K16: Turbo 15T | L16: Tata 0.7T
B17: Fuel cost per km at 0% return loads | C17: 0 | D17: ='Master Sheet'!D116 -> 4.7417273 | E17: ='Master Sheet'!E116 -> 4.7417273 | F17: ='Master Sheet'!F116 -> 5.1535273 | G17: ='Master Sheet'!G116 -> 5.6852222 | H17: ='Master Sheet'!H116 -> 6.027 | I17: ='Master Sheet'!I116 -> 9.7599333 | J17: ='Master Sheet'!J116 -> 14.236929 | K17: ='Master Sheet'!K116 -> 11.929 | L17: ='Master Sheet'!L116 -> #DIV/0!
B18: Fuel cost per km at 30% return loads | C18: 0.3 | D18: ='Master Sheet'!D117 -> 4.6746591 | E18: ='Master Sheet'!E117 -> 4.6746591 | F18: ='Master Sheet'!F117 -> 5.2340091 | G18: ='Master Sheet'!G117 -> 5.7835889 | H18: ='Master Sheet'!H117 -> 6.248325 | I18: ='Master Sheet'!I117 -> 10.055033 | J18: ='Master Sheet'!J117 -> 14.553107 | K18: ='Master Sheet'!K117 -> 12.37165 | L18: ='Master Sheet'!L117 -> #DIV/0!
B19: Fuel cost per km at 40% return loads | C19: 0.4 | D19: ='Master Sheet'!D118 -> 4.652303 | E19: ='Master Sheet'!E118 -> 4.652303 | F19: ='Master Sheet'!F118 -> 5.2608364 | G19: ='Master Sheet'!G118 -> 5.8163778 | H19: ='Master Sheet'!H118 -> 6.3221 | I19: ='Master Sheet'!I118 -> 10.1534 | J19: ='Master Sheet'!J118 -> 14.6585 | K19: ='Master Sheet'!K118 -> 12.5192 | L19: ='Master Sheet'!L118 -> #DIV/0!
B20: Fuel cost per km at 50% return loads | C20: 0.5 | D20: ='Master Sheet'!D119 -> 4.629947 | E20: ='Master Sheet'!E119 -> 4.629947 | F20: ='Master Sheet'!F119 -> 5.2876636 | G20: ='Master Sheet'!G119 -> 5.8491667 | H20: ='Master Sheet'!H119 -> 6.395875 | I20: ='Master Sheet'!I119 -> 10.251767 | J20: ='Master Sheet'!J119 -> 14.763893 | K20: ='Master Sheet'!K119 -> 12.66675 | L20: ='Master Sheet'!L119 -> #DIV/0!
B21: Fuel cost per km at 60% return loads | C21: 0.6 | D21: ='Master Sheet'!D120 -> 4.6075909 | E21: ='Master Sheet'!E120 -> 4.6075909 | F21: ='Master Sheet'!F120 -> 5.3144909 | G21: ='Master Sheet'!G120 -> 5.8819556 | H21: ='Master Sheet'!H120 -> 6.46965 | I21: ='Master Sheet'!I120 -> 10.350133 | J21: ='Master Sheet'!J120 -> 14.869286 | K21: ='Master Sheet'!K120 -> 12.8143 | L21: ='Master Sheet'!L120 -> #DIV/0!
B22: Fuel cost per km at 80% return loads | C22: 0.8 | D22: ='Master Sheet'!D121 -> 4.5628788 | E22: ='Master Sheet'!E121 -> 4.5628788 | F22: ='Master Sheet'!F121 -> 5.3681455 | G22: ='Master Sheet'!G121 -> 5.9475333 | H22: ='Master Sheet'!H121 -> 6.6172 | I22: ='Master Sheet'!I121 -> 10.546867 | J22: ='Master Sheet'!J121 -> 15.080071 | K22: ='Master Sheet'!K121 -> 13.1094 | L22: ='Master Sheet'!L121 -> #DIV/0!
B23: Fuel cost per km at 100% return loads | C23: 1 | D23: ='Master Sheet'!D122 -> 4.5181667 | E23: ='Master Sheet'!E122 -> 4.5181667 | F23: ='Master Sheet'!F122 -> 5.4218 | G23: ='Master Sheet'!G122 -> 6.0131111 | H23: ='Master Sheet'!H122 -> 6.76475 | I23: ='Master Sheet'!I122 -> 10.7436 | J23: ='Master Sheet'!J122 -> 15.290857 | K23: ='Master Sheet'!K122 -> 13.4045 | L23: ='Master Sheet'!L122 -> #DIV/0!
B26: Tyre Cost Per km
B27: Truck Type | C27: Rate | D27: Tempo 2T 3W | E27: Tempo 2T 4W | F27: Canter 4T | G27: Canter 6.5T | H27: Canter 8.5T | I27: Truck 9T | J27: Container 14T | K27: Turbo 15T | L27: Tata 0.7T
B28: Tyre Cost per Km | D28: ='Master Sheet'!D130 -> 1.225 | E28: ='Master Sheet'!E130 -> 1.225 | F28: ='Master Sheet'!F130 -> 1.225 | G28: ='Master Sheet'!G130 -> 1.4 | H28: ='Master Sheet'!H130 -> 2.1 | I28: ='Master Sheet'!I130 -> 2.625 | J28: ='Master Sheet'!J130 -> 4.0833333 | K28: ='Master Sheet'!K130 -> 4.9 | L28: ='Master Sheet'!L130 -> #DIV/0!
B31: Maintenance Per km
B32: Truck Type | C32: Rate | D32: Tempo 2T 3W | E32: Tempo 2T 4W | F32: Canter 4T | G32: Canter 6.5T | H32: Canter 8.5T | I32: Truck 9T | J32: Container 14T | K32: Turbo 15T | L32: Tata 0.7T
B33: Total Maintenance Cost per Km | D33: =SUM(D34:D41) -> 0.39088125 | E33: =SUM(E34:E41) -> 0.39088125 | F33: =SUM(F34:F41) -> 0.40393125 | G33: =SUM(G34:G41) -> 0.42856429 | H33: =SUM(H34:H41) -> 0.42856429 | I33: =SUM(I34:I41) -> 0.43938571 | J33: =SUM(J34:J41) -> 0.66575238 | K33: =SUM(K34:K41) -> 0 | L33: =SUM(L34:L41) -> 0
B34: ='Master Sheet'!B144 -> Engine Oil Cost per Km | D34: ='Master Sheet'!D144 -> 0.078375 | E34: ='Master Sheet'!E144 -> 0.078375 | F34: ='Master Sheet'!F144 -> 0.078375 | G34: ='Master Sheet'!G144 -> 0.089571429 | H34: ='Master Sheet'!H144 -> 0.089571429 | I34: ='Master Sheet'!I144 -> 0.089571429 | J34: ='Master Sheet'!J144 -> 0.12214286
B35: ='Master Sheet'!B148 -> Gearbox Oil Cost per Km | D35: ='Master Sheet'!D148 -> 0.013275 | E35: ='Master Sheet'!E148 -> 0.013275 | F35: ='Master Sheet'!F148 -> 0.013275 | G35: ='Master Sheet'!G148 -> 0.019666667 | H35: ='Master Sheet'!H148 -> 0.019666667 | I35: ='Master Sheet'!I148 -> 0.019666667 | J35: ='Master Sheet'!J148 -> 0.027533333
B36: ='Master Sheet'!B152 -> Axle (crown) Oil Cost per Km | D36: ='Master Sheet'!D152 -> 0.01603125 | E36: ='Master Sheet'!E152 -> 0.01603125 | F36: ='Master Sheet'!F152 -> 0.01603125 | G36: ='Master Sheet'!G152 -> 0.0171 | H36: ='Master Sheet'!H152 -> 0.0171 | I36: ='Master Sheet'!I152 -> 0.0171 | J36: ='Master Sheet'!J152 -> 0.0456
B37: ='Master Sheet'!B156 -> Coolant Cost per Km | D37: ='Master Sheet'!D156 -> 0.005 | E37: ='Master Sheet'!E156 -> 0.005 | F37: ='Master Sheet'!F156 -> 0.0125 | G37: ='Master Sheet'!G156 -> 0.013333333 | H37: ='Master Sheet'!H156 -> 0.013333333 | I37: ='Master Sheet'!I156 -> 0.013333333 | J37: ='Master Sheet'!J156 -> 0.013333333
B38: ='Master Sheet'!B160 -> Fuel filter Cost per Km | D38: ='Master Sheet'!D160 -> 0.036 | E38: ='Master Sheet'!E160 -> 0.036 | F38: ='Master Sheet'!F160 -> 0.036 | G38: ='Master Sheet'!G160 -> 0.041142857 | H38: ='Master Sheet'!H160 -> 0.041142857 | I38: ='Master Sheet'!I160 -> 0.048 | J38: ='Master Sheet'!J160 -> 0.085714286
B39: ='Master Sheet'!B163 -> Air filter Cost per Km | D39: ='Master Sheet'!D163 -> 0.0222 | E39: ='Master Sheet'!E163 -> 0.0222 | F39: ='Master Sheet'!F163 -> 0.02775 | G39: ='Master Sheet'!G163 -> 0.02775 | H39: ='Master Sheet'!H163 -> 0.02775 | I39: ='Master Sheet'!I163 -> 0.031714286 | J39: ='Master Sheet'!J163 -> 0.031428571
B40: Battery Cost per Km | D40: ='Master Sheet'!D166 -> 0.12 | E40: ='Master Sheet'!E166 -> 0.12 | F40: ='Master Sheet'!F166 -> 0.12 | G40: ='Master Sheet'!G166 -> 0.12 | H40: ='Master Sheet'!H166 -> 0.12 | I40: ='Master Sheet'!I166 -> 0.12 | J40: ='Master Sheet'!J166 -> 0.24
B41: Contigency Cost per Km | C41: 0.1 | D41: =$C41 -> 0.1 | E41: =$C41 -> 0.1 | F41: =$C41 -> 0.1 | G41: =$C41 -> 0.1 | H41: =$C41 -> 0.1 | I41: =$C41 -> 0.1 | J41: =$C41 -> 0.1
B44: Overhead Cost Per km
B45: Truck Type | C45: Rate | D45: Tempo 2T 3W | E45: Tempo 2T 4W | F45: Canter 4T | G45: Canter 6.5T | H45: Canter 8.5T | I45: Truck 9T | J45: Container 14T | K45: Turbo 15T | L45: Tata 0.7T
B46: Overhead cost (over fixed & variable) | C46: =Guidelines!$C$27 -> 0.07 | D46: =$C46*(D6+D17+D28+D33) -> 0.70110507 | E46: =$C46*(E6+E17+E28+E33) -> 0.70110507 | F46: =$C46*(F6+F17+F28+F33) -> 0.8908301 | G46: =$C46*(G6+G17+G28+G33) -> 0.96208819 | H46: =$C46*(H6+H17+H28+H33) -> 1.0619153 | I46: =$C46*(I6+I17+I28+I33) -> 1.3998572 | J46: =$C46*(J6+J17+J28+J33) -> 1.9825929 | K46: =$C46*(K6+K17+K28+K33) -> 1.7720694 | L46: =$C46*(L6+L17+L28+L33) -> #DIV/0!
B49: Returns Per Km
B50: Truck Type | C50: Rate | D50: Tempo 2T 3W | E50: Tempo 2T 4W | F50: Canter 4T | G50: Canter 6.5T | H50: Canter 8.5T | I50: Truck 9T | J50: Container 14T | K50: Turbo 15T | L50: Tata 0.7T
B51: Profit (over fixed & variable) | C51: =Guidelines!$C$28 -> 0.1 | D51: =$C51*(D6+D17+D28+D33) -> 1.0015787 | E51: =$C51*(E6+E17+E28+E33) -> 1.0015787 | F51: =$C51*(F6+F17+F28+F33) -> 1.2726144 | G51: =$C51*(G6+G17+G28+G33) -> 1.3744117 | H51: =$C51*(H6+H17+H28+H33) -> 1.5170218 | I51: =$C51*(I6+I17+I28+I33) -> 1.999796 | J51: =$C51*(J6+J17+J28+J33) -> 2.8322756 | K51: =$C51*(K6+K17+K28+K33) -> 2.5315277 | L51: =$C51*(L6+L17+L28+L33) -> #DIV/0!
...

Sheet Search Index
B1: Previous | G1: Main-Page
A2: Project Unnati
B4: ZBC Index File
B5: Truck Type | C5: Return Load | D5: Look-up Value | E5: PTPK | F5: PT | G5: Per Trip
B6: Tempo 2T 3W | C6: 0 | D6: =CONCATENATE(B6,C6) -> Tempo 2T 3W0 | E6: ='ZBC-Calculations'!D80 -> 10.898413 | F6: ='ZBC-Calculations'!D91 -> 24238.071 | G6: ='ZBC-Calculations'!D102 -> 106647.51
B7: Tempo 2T 3W | C7: 0.3 | D7: =CONCATENATE(B7,C7) -> Tempo 2T 3W0.3 | E7: ='ZBC-Calculations'!D81 -> 9.2118258 | F7: ='ZBC-Calculations'!D92 -> 20487.101 | G7: ='ZBC-Calculations'!D103 -> 76621.756
B8: Tempo 2T 3W | C8: 0.4 | D8: =CONCATENATE(B8,C8) -> Tempo 2T 3W0.4 | E8: ='ZBC-Calculations'!D82 -> 8.6536948 | F8: ='ZBC-Calculations'!D93 -> 19245.817 | G8: ='ZBC-Calculations'!D104 -> 67745.276
B9: Tempo 2T 3W | C9: 0.5 | D9: =CONCATENATE(B9,C9) -> Tempo 2T 3W0.5 | E9: ='ZBC-Calculations'!D83 -> 8.0975961 | F9: ='ZBC-Calculations'!D94 -> 18009.054 | G9: ='ZBC-Calculations'!D105 -> 59429.877
B10: Tempo 2T 3W | C10: 0.6 | D10: =CONCATENATE(B10,C10) -> Tempo 2T 3W0.6 | E10: ='ZBC-Calculations'!D84 -> 7.5435298 | F10: ='ZBC-Calculations'!D95 -> 16776.81 | G10: ='ZBC-Calculations'!D106 -> 51672.575
B11: Tempo 2T 3W | C11: 0.8 | D11: =CONCATENATE(B11,C11) -> Tempo 2T 3W0.8 | E11: ='ZBC-Calculations'!D85 -> 6.4414942 | F11: ='ZBC-Calculations'!D96 -> 14325.883 | G11: ='ZBC-Calculations'!D107 -> 37820.332
B12: Tempo 2T 3W | C12: 1 | D12: =CONCATENATE(B12,C12) -> Tempo 2T 3W1 | E12: ='ZBC-Calculations'!D86 -> 5.3475882 | F12: ='ZBC-Calculations'!D97 -> 11893.036 | G12: ='ZBC-Calculations'!D108 -> 26164.679
B13: Tempo 2T 4W | C13: 0 | D13: =CONCATENATE(B13,C13) -> Tempo 2T 4W0 | E13: ='ZBC-Calculations'!E80 -> 6.1954804 | F13: ='ZBC-Calculations'!E91 -> 13778.748 | G13: ='ZBC-Calculations'!E102 -> 106647.51
B14: Tempo 2T 4W | C14: 0.3 | D14: =CONCATENATE(B14,C14) -> Tempo 2T 4W0.3 | E14: ='ZBC-Calculations'!E81 -> 5.2366969 | F14: ='ZBC-Calculations'!E92 -> 11646.414 | G14: ='ZBC-Calculations'!E103 -> 76621.756
B15: Tempo 2T 4W | C15: 0.4 | D15: =CONCATENATE(B15,C15) -> Tempo 2T 4W0.4 | E15: ='ZBC-Calculations'!E82 -> 4.919413 | F15: ='ZBC-Calculations'!E93 -> 10940.775 | G15: ='ZBC-Calculations'!E104 -> 67745.276
B16: Tempo 2T 4W | C16: 0.5 | D16: =CONCATENATE(B16,C16) -> Tempo 2T 4W0.5 | E16: ='ZBC-Calculations'!E83 -> 4.6032846 | F16: ='ZBC-Calculations'!E94 -> 10237.705 | G16: ='ZBC-Calculations'!E105 -> 59429.877
B17: Tempo 2T 4W | C17: 0.6 | D17: =CONCATENATE(B17,C17) -> Tempo 2T 4W0.6 | E17: ='ZBC-Calculations'!E84 -> 4.2883115 | F17: ='ZBC-Calculations'!E95 -> 9537.2048 | G17: ='ZBC-Calculations'!E106 -> 51672.575
B18: Tempo 2T 4W | C18: 0.8 | D18: =CONCATENATE(B18,C18) -> Tempo 2T 4W0.8 | E18: ='ZBC-Calculations'!E85 -> 3.6618313 | F18: ='ZBC-Calculations'!E96 -> 8143.9129 | G18: ='ZBC-Calculations'!E107 -> 37820.332
B19: Tempo 2T 4W | C19: 1 | D19: =CONCATENATE(B19,C19) -> Tempo 2T 4W1 | E19: ='ZBC-Calculations'!E86 -> 3.0399726 | F19: ='ZBC-Calculations'!E97 -> 6760.8991 | G19: ='ZBC-Calculations'!E108 -> 26164.679
B20: Canter 4T | C20: 0 | D20: =CONCATENATE(B20,C20) -> Canter 4T0 | E20: ='ZBC-Calculations'!F80 -> 7.5796865 | F20: ='ZBC-Calculations'!F91 -> 16857.223 | G20: ='ZBC-Calculations'!F102 -> 134857.78
B21: Canter 4T | C21: 0.3 | D21: =CONCATENATE(B21,C21) -> Canter 4T0.3 | E21: ='ZBC-Calculations'!F81 -> 6.4769383 | F21: ='ZBC-Calculations'!F92 -> 14404.711 | G21: ='ZBC-Calculations'!F103 -> 97952.033
B22: Canter 4T | C22: 0.4 | D22: =CONCATENATE(B22,C22) -> Canter 4T0.4 | E22: ='ZBC-Calculations'!F82 -> 6.1066728 | F22: ='ZBC-Calculations'!F93 -> 13581.24 | G22: ='ZBC-Calculations'!F104 -> 86919.938
B23: Canter 4T | C23: 0.5 | D23: =CONCATENATE(B23,C23) -> Canter 4T0.5 | E23: ='ZBC-Calculations'!F83 -> 5.735066 | F23: ='ZBC-Calculations'!F94 -> 12754.787 | G23: ='ZBC-Calculations'!F105 -> 76528.72
B24: Canter 4T | C24: 0.6 | D24: =CONCATENATE(B24,C24) -> Canter 4T0.6 | E24: ='ZBC-Calculations'!F84 -> 5.3621178 | F24: ='ZBC-Calculations'!F95 -> 11925.35 | G24: ='ZBC-Calculations'!F106 -> 66781.96 | I24: Tata 0.7T
B25: Canter 4T | C25: 0.8 | D25: =CONCATENATE(B25,C25) -> Canter 4T0.8 | E25: ='ZBC-Calculations'!F85 -> 4.6121973 | F25: ='ZBC-Calculations'!F96 -> 10257.527 | G25: ='ZBC-Calculations'!F107 -> 49236.129
B26: Canter 4T | C26: 1 | D26: =CONCATENATE(B26,C26) -> Canter 4T1 | E26: ='ZBC-Calculations'!F86 -> 3.8569114 | F26: ='ZBC-Calculations'!F97 -> 8577.771 | G26: ='ZBC-Calculations'!F108 -> 34311.084
B27: Canter 6.5T | C27: 0 | D27: =CONCATENATE(B27,C27) -> Canter 6.5T0 | E27: ='ZBC-Calculations'!G80 -> 4.3954048 | F27: ='ZBC-Calculations'!G91 -> 9775.3804 | G27: ='ZBC-Calculations'!G102 -> 145653.17
B28: Canter 6.5T | C28: 0.3 | D28: =CONCATENATE(B28,C28) -> Canter 6.5T0.3 | E28: ='ZBC-Calculations'!G81 -> 3.7585402 | F28: ='ZBC-Calculations'!G92 -> 8358.9934 | G28: ='ZBC-Calculations'!G103 -> 105866.65
B29: Canter 6.5T | C29: 0.4 | D29: =CONCATENATE(B29,C29) -> Canter 6.5T0.4 | E29: ='ZBC-Calculations'!G82 -> 3.5444915 | F29: ='ZBC-Calculations'!G93 -> 7882.9491 | G29: ='ZBC-Calculations'!G104 -> 93964.754
B30: Canter 6.5T | C30: 0.5 | D30: =CONCATENATE(B30,C30) -> Canter 6.5T0.5 | E30: ='ZBC-Calculations'!G83 -> 3.3295626 | F30: ='ZBC-Calculations'!G94 -> 7404.9472 | G30: ='ZBC-Calculations'!G105 -> 82750.285
B31: Canter 6.5T | C31: 0.6 | D31: =CONCATENATE(B31,C31) -> Canter 6.5T0.6 | E31: ='ZBC-Calculations'!G84 -> 3.1137534 | F31: ='ZBC-Calculations'!G95 -> 6924.9876 | G31: ='ZBC-Calculations'!G106 -> 72227.621
B32: Canter 6.5T | C32: 0.8 | D32: =CONCATENATE(B32,C32) -> Canter 6.5T0.8 | E32: ='ZBC-Calculations'!G85 -> 2.6794944 | F32: ='ZBC-Calculations'!G96 -> 5959.1955 | G32: ='ZBC-Calculations'!G107 -> 53275.207
B33: Canter 6.5T | C33: 1 | D33: =CONCATENATE(B33,C33) -> Canter 6.5T1 | E33: ='ZBC-Calculations'!G86 -> 2.2417144 | F33: ='ZBC-Calculations'!G97 -> 4985.5727 | G33: ='ZBC-Calculations'!G108 -> 37142.517
B34: Canter 8.5T | C34: 0 | D34: =CONCATENATE(B34,C34) -> Canter 8.5T0 | E34: ='ZBC-Calculations'!H80 -> 4.2450403 | F34: ='ZBC-Calculations'!H91 -> 9440.9697 | G34: ='ZBC-Calculations'!H102 -> 160496.48
B35: Canter 8.5T | C35: 0.3 | D35: =CONCATENATE(B35,C35) -> Canter 8.5T0.3 | E35: ='ZBC-Calculations'!H81 -> 3.6525493 | F35: ='ZBC-Calculations'!H92 -> 8123.2696 | G35: ='ZBC-Calculations'!H103 -> 117381.25
B36: Canter 8.5T | C36: 0.4 | D36: =CONCATENATE(B36,C36) -> Canter 8.5T0.4 | E36: ='ZBC-Calculations'!H82 -> 3.4515805 | F36: ='ZBC-Calculations'!H93 -> 7676.315 | G36: ='ZBC-Calculations'!H104 -> 104397.88
B37: Canter 8.5T | C37: 0.5 | D37: =CONCATENATE(B37,C37) -> Canter 8.5T0.5 | E37: ='ZBC-Calculations'!H83 -> 3.2488758 | F37: ='ZBC-Calculations'!H94 -> 7225.4998 | G37: ='ZBC-Calculations'!H105 -> 92125.123
B38: Canter 8.5T | C38: 0.6 | D38: =CONCATENATE(B38,C38) -> Canter 8.5T0.6 | E38: ='ZBC-Calculations'!H84 -> 3.0444353 | F38: ='ZBC-Calculations'!H95 -> 6770.8241 | G38: ='ZBC-Calculations'!H106 -> 80572.806
B39: Canter 8.5T | C39: 0.8 | D39: =CONCATENATE(B39,C39) -> Canter 8.5T0.8 | E39: ='ZBC-Calculations'!H85 -> 2.6303465 | F39: ='ZBC-Calculations'!H96 -> 5849.8907 | G39: ='ZBC-Calculations'!H107 -> 59668.885
B40: Canter 8.5T | C40: 1 | D40: =CONCATENATE(B40,C40) -> Canter 8.5T1 | E40: ='ZBC-Calculations'!H86 -> 2.2093143 | F40: ='ZBC-Calculations'!H97 -> 4913.5149 | G40: ='ZBC-Calculations'!H108 -> 41764.877
B41: Truck 9T | C41: 0 | D41: =CONCATENATE(B41,C41) -> Truck 9T0 | E41: ='ZBC-Calculations'!I80 -> 4.4280148 | F41: ='ZBC-Calculations'!I91 -> 9847.905 | G41: ='ZBC-Calculations'!I102 -> 210745.17
...

Sheet Distance Matrix
B2: DIBRUGARH | C2: GUWAHATI | D2: SILCHER | E2: ARA | F2: ARIYA | G2: BEGUSARAI | H2: BETIYA | I2: BHAGALPUR | J2: BIHARSHARIF | K2: CHAPRA | L2: DAIRYON-SON | M2: DALTONGANJ | N2: DARBANGHA | O2: GAYA | P2: HAZIPUR | Q2: KISHANGANJ | R2: MOTIHARI | S2: MUJJAFARPUR | T2: MUNGER | U2: PATNA | V2: PURNEA | W2: SAHARSA | X2: SAMASTIPUR | Y2: SASARAM | Z2: SIWAN | AA2: RAIGARH | AB2: RAIPUR | AC2: AASHRAM BHOGAL | AD2: AIMS DELHI | AE2: AJMERI GATE | AF2: ALIPUR | AG2: AMBA CINEMA | AH2: ANAND PARVAT | AI2: ANAND VIHAR | AJ2: ANDHERIA MORE | AK2: APOLLO HOSP. JASOLA | AL2: AZAD MARKET | AM2: AZADPUR | AN2: BADERPUR | AO2: BADLI | AP2: BASANT KUNJ | AQ2: BAWANA | AR2: BEGAM PUR | AS2: BHAJANPURA | AT2: BUD PUR | AU2: BUDH VIHAR | AV2: BURADI | AW2: CAMPUS | AX2: CHANDNI CHOWK | AY2: CHATTERPUR | AZ2: CHAWLA | BA2: CHAWRI BAZAR | BB2: CHHATTERPUR | BC2: CHIRAG DELHI | BD2: CONNAUGHT PLACE | BE2: DAYABASTI | BF2: DEFENCE COLONY | BG2: DELHI CANT | BH2: DELHI GATE | BI2: DEV NAGAR | BJ2: DHOLA KUAN | BK2: DWARKA | BL2: FATEHPURI | BM2: GAZIPUR | BN2: GHEVARA MOD (DELHI DEPOT) | BO2: GREATER KAILASH | BP2: GREEN PARK | BQ2: GURGAON VIA DELHI | BR2: HAIDERPUR | BS2: HIRAN KUDNA | BT2: I.I.T | BU2: I.T.O. | BV2: INDERLOK | BW2: INDIA GATE | BX2: JAGATPURI | BY2: JANAKPURI | BZ2: JHANDE WALAN | CA2: KAD KAD DUMA | CB2: KALKA | CC2: KAMLA MARKET | CD2: KANJHAWLA | CE2: KAPASHEDA | CF2: KARAWAL NAGAR | CG2: KARNAL BYE PASS | CH2: KAROL BAGH | CI2: KHANNA MARKET | CJ2: KHANPUR | CK2: KHARI BAWRI | CL2: KIRTI NAGAR | CM2: KISHAN GANJ | CN2: KOTLA | CO2: KUNDLI BORDER | CP2: LAHORI GATE | CQ2: LAJPAT NAGAR | CR2: LAKSHMI NAGAR | CS2: LAL QUILLA | CT2: LIBAS PUR | CU2: LODHI GATE | CV2: MADIPUR | CW2: MAHARANA P. BAGH | CX2: MAHIPAL PUR | CY2: MALVIYA NAGAR | CZ2: MANGOL PURI | DA2: MANSEROVER GARDEN | DB2: MAYA PURI | DC2: MAYUR VIHAR | DD2: MEHROLLI | DE2: MINTO BRIDGE | DF2: MODEL TOWN | DG2: MORI GATE | DH2: MOTI NAGAR | DI2: MOTIA KHAN | DJ2: MUDRIKA | DK2: MUNDKA | DL2: NAND NAGARI | DM2: NANGLOI | DN2: NANGLOI VIA DEPOT | DO2: NARELA | DP2: NARYANA | DQ2: NAYA BAZAAR | DR2: NAZAFGARH | DS2: NEHRU PLACE | DT2: NEW FRIENDS COLONY | DU2: NIZAMUDDIN | DV2: NOVALTY | DW2: OCHANDI BORDER | DX2: OKHLA | DY2: PANDAV NAGAR | DZ2: PAPANKALAN | EA2: PASHCHIM VIHAR | EB2: PATEL NAGAR | EC2: PATPAD GUNJ | ED2: PEERAGADHI | EE2: PRITAM PURA | EF2: PUDH PARHLAD PUR | EG2: PUNJABI BAGH | EH2: R.K. PURAM | EI2: RAJA GARDEN | EJ2: RAM MANOHAR LOHIA HOSP | EK2: RAMA ROAD | EL2: RAMPURA | EM2: RITHALA | EN2: RITHALA DEPOT | EO2: ROHINI | EP2: SAFDERGUNJ | EQ2: SAKET | ER2: SANJAY GANDHI | ES2: SARAI ROHILLA | ET2: SARITA VIHAR | EU2: SAROJNI NAGAR | EV2: SERITA VIHAR | EW2: SEROJNI NAGAR | EX2: SHADIPUR | EY2: SHAHADERA | EZ2: SHAHBAD DAIRY | FA2: SHAKTI NAGAR | FB2: SHANKER ROAD | FC2: SHILAM PUR | FD2: SINDHU BORDER | FE2: SIRAS PUR | FF2: SMALKHAN | FG2: SOUTH EXTENSION | FH2: SUBHASH NAGAR | FI2: SWAVROOP NAGAR | FJ2: TIKRI | FK2: TILK NAGAR | FL2: TIMARPUR | FM2: TIS HAZAREE | FN2: TRINAGAR | FO2: TUGALKABAD | FP2: UDYOG NAGAR | FQ2: UTTAM NAGAR | FR2: VIKAS PURI | FS2: WAZIRABAD | FT2: WAZIRPUR | FU2: ZAHANGEER PURI | FV2: ZAKHEERA | FW2: AHMEDABAD | FX2: BARODA | FY2: GHANDHI NAGAR | FZ2: JAMNAGAR | GA2: KANDALA | GB2: VARODADA | GC2: ADAM PUR MANDI | GD2: AGROHA | GE2: AILANABAD | GF2: AMBALA | GG2: ASSANDH | GH2: ATELI MANDI | GI2: BADKALI CHWOK | GJ2: BADSHAH PUR | GK2: BAHADURGARH LOCAL | GL2: BALLABH GARH | GM2: BALLABHGARH | GN2: BAMDOLI | GO2: BARHIMURTHAL | GP2: BARWALA | GQ2: BAWAL | GR2: BERI | GS2: BHIWANI | GT2: BILASPUR CHOWK | GU2: BURELL | GV2: DABODH | GW2: DABWALI | GX2: DADRI | GY2: DHARUHEDA | GZ2: ELLANABAD | HA2: FARIDABAD | HB2: FARRKHNAGAR | HC2: FATEHABAD | HD2: GANDHARA | HE2: GANNAUR | HF2: GOHANA | HG2: GREATER NOIDA | HH2: GUHANA | HI2: GULHA / CHIKA | HJ2: GURGAON | HK2: HANSI | HL2: HATHEEN | HM2: HELI MANDI | HN2: HISSAR | HO2: HODAL | HP2: INDRI LADWA | HQ2: ISHER HEDI | HR2: JHAJJAR | HS2: JIND | HT2: JULANA | HU2: KAITHAL | HV2: KANINA | HW2: KANONDHA KULASI | HX2: KARNAL | HY2: KHARKHODA | HZ2: KOSI BORDER | IA2: KOSLI | IB2: KURUKSHETRA | IC2: LADRAWAN | ID2: LAKHAN MAJRA | IE2: LUHARU | IF2: MACHROLI | IG2: MAHAM | IH2: MAHENDER GARH | II2: MANESER | IJ2: MATLODHA | IK2: MUNDHAL | IL2: MURTHAL | IM2: NARNAUL | IN2: NARWANA | IO2: NARYAN GARH | IP2: NORANG PUR | IQ2: NUHU | IR2: PALWAL | IS2: PANCHKULA | IT2: PANHANA | IU2: PANIPAT | IV2: PATOWDI | IW2: PEEPLI | IX2: PEHWA | IY2: PILANI | IZ2: PUNDREE | JA2: REWARI | JB2: ROHTAK | JC2: SAFIDO | JD2: SAHALAWAS | JE2: SAMALKHAN | JF2: SAMPLA | JG2: SATNALI | JH2: SHAHABAD | JI2: SIRSA | JJ2: SOHANA | JK2: SOHTI | JL2: SONIPAT | JM2: SURAJKUND | JN2: TAUDU | JO2: TOHANA | JP2: TOSHAM | JQ2: UKLANA | JR2: YAMUNANAGAR | JS2: ZULANA | JT2: BADDHI | JU2: BAIJ NATH | JV2: DEHRA | JW2: HAMIRPUR | JX2: JASSAUR | JY2: MANDI | JZ2: PADIALA | KA2: SHIMLA | KB2: SOLAN | KC2: ANANTNAG | KD2: BARAMULA | KE2: JAMMU | KF2: KATWA | KG2: PAMPORE | KH2: PHULWAMA | KI2: SRINAGAR | KJ2: UDAMPUR | KK2: CHAS | KL2: DEO GHAR | KM2: DHANBAD | KN2: JAMSHEDPUR | KO2: RANCHI | KP2: UDUPI | KQ2: BANGALORE | KR2: BEENA | KS2: BHOPAL | KT2: CHINDWARA | KU2: CHITRAKOOT | KV2: GWALIOR | KW2: INDORE | KX2: JABALPUR | KY2: KHUJRAHO | KZ2: REWA | LA2: SAGAR | LB2: SANGROLI | LC2: SATNA | LD2: AURANGABAD | LE2: BHIWANDI | LF2: GOA | LG2: KOLHAPUR | LH2: MUMBAI | LI2: NAGPUR | LJ2: NASIK | LK2: PUNE | LL2: ULAHS NAGAR | LM2: BEHRAMPUR | LN2: BHUBNESHWAR | LO2: JAJPUR | LP2: ABOHAR | LQ2: AHMEDGARH | LR2: AMRITSER | LS2: BANUR | LT2: BARNALA | LU2: BATALA | LV2: BHATINDA | LW2: DHURI | LX2: FAJILKA | LY2: FARIDKOT | LZ2: FEROZPUR | MA2: GURDAS PUR | MB2: HOSHIYARPUR | MC2: JALLANDHAR | MD2: KAPOOR THALA | ME2: KHANNA | MF2: KHANOURI | MG2: KHARAR | MH2: LUDHIANA | MI2: MALER KOTLA | MJ2: MALHOT | MK2: MANSA | ML2: MOGHA | MM2: MOHALI | MN2: MUKTESHWAR | MO2: MULANPUR | MP2: NAWA SHAHAR | MQ2: PATDA | MR2: PATHANKOT | MS2: PATIYALA | MT2: PHAGWARA | MU2: RAJPURA | MV2: RAMPUR PHOOL | MW2: ROPAD MERINDA | MX2: SANGRUR | MY2: SIMANA | MZ2: TALVANDI | NA2: THARA | NB2: ZIRAKPUR | NC2: AJMER | ND2: ALWAR | NE2: BADMER | NF2: BANDI KUE | NG2: BEHROD | NH2: BHILWARA | NI2: BHIWADI | NJ2: BIKANER | NK2: BYAVER | NL2: CHHITOR GARH | NM2: CHIRAWA | NN2: HANUMAN GARH | NO2: JAIPUR | NP2: JAISALMER | NQ2: JHUNJHUNU | NR2: JODHPUR | NS2: KHETDI | NT2: KISHAN GARH | NU2: KOTA | NV2: KOTA BUNDI | NW2: KOTPUTLI | NX2: PUSHKAR | NY2: RAJ GARH | NZ2: SALASAR | OA2: SHAHPUR | OB2: SIKKAR | OC2: SRI GANGANAGAR | OD2: SRI SAHALASAR BALA JI | OE2: SUJAN GARH | OF2: SURAT GARH | OG2: UDAIPUR | OH2: CHENNAI | OI2: BIBINAGAR | OJ2: HYDERABAD | OK2: ISHNAPUR | OL2: KOCHI | OM2: KOJIKURE | ON2: AGARTALA | OO2: CHANDIGARH | OP2: AGRA | OQ2: AJAMGARH | OR2: ALIGARH | OS2: ALLAHABAD | OT2: AMETHI | OU2: BAGPAT | OV2: BAREILLY | OW2: BHARICH | OX2: BHINGA | OY2: BULAND SHAHER | OZ2: CHHAPROLA | PA2: DORALA | PB2: GAJROLA | PC2: GARH GANGA | PD2: GHAZIABAD | PE2: GONDA | PF2: GORAKHPUR | PG2: HAPUR | PH2: HARDOI | PI2: JAISH | PJ2: JHANSI | PK2: KANPUR | PL2: KHATOLI | PM2: KHEKDA BIJNORE | PN2: KHURJA | PO2: KUNDA | PP2: LALITPUR | PQ2: LUCKNOW | PR2: MATHURA | PS2: MAU SHADAPUR | PT2: MEERUT | PU2: MURADABAD | PV2: MURADNAGAR | PW2: MUZZAFERNAGAR | PX2: NANPARA | PY2: NOIDA | PZ2: PILI BHIT | QA2: PILKHUVA | QB2: RAI BAREILLY | QC2: VARANASI-RAMNAGHAR | QD2: SAHARANPUR | QE2: SAHIBABAD | QF2: VARANASI-SHADPUR | QG2: SHAMLI | QH2: SIKANDERA BAD | QI2: SIKOHABAD | QJ2: SULTANPUR | QK2: U.P. BORDER | QL2: VARANASI | QM2: ALMORA | QN2: BAJPUR | QO2: DEHRADUN | QP2: GARHWAL | QQ2: HALDWANI | QR2: HARIDWAR | QS2: KASHIPUR | QT2: KICHHA | QU2: KOT DWAR | QV2: MANSURI | QW2: PITHORAGARH | QX2: RISHIKESH | QY2: RUDERPUR | QZ2: ROORKEE | RA2: SITARGUNJ | RB2: ASANSOL | RC2: BANKURA | RD2: BEENAGUDI | RE2: BEHRAM PUR | RF2: BHOLPUR | RG2: BURDWAN | RH2: DIGA BAJPUR EAST MINDNAPUR | RI2: DURGAPUR | RJ2: GANGARAMPUR | RK2: JAIGOAN | RL2: JALPAIGURI | RM2: JHARGRAM | RN2: KATHUA | RO2: KOLKATA | RP2: MALDA | RQ2: MIDNA PUR | RR2: RANI GANJ | RS2: SILIGURI
A3: BAHADURGARH | B3: 2361 | C3: 1959 | D3: 2377 | E3: 1029 | F3: 1367 | G3: 1242 | H3: 1020 | I3: 1309 | J3: 1124 | K3: 1039 | L3: 973 | M3: 1091 | N3: 1191 | O3: 1087 | P3: 1118 | Q3: 1354 | R3: 1072 | S3: 1108 | T3: 1270 | U3: 1080 | V3: 1416 | W3: 1333 | X3: 1164 | Y3: 951 | Z3: 1005 | AA3: 1295 | AB3: 1243 | AC3: 0 | AD3: 30 | AE3: 0 | AF3: 35 | AG3: 0 | AH3: 0 | AI3: 0 | AJ3: 0 | AK3: 0 | AL3: 0 | AM3: 0 | AN3: 53 | AO3: 0 | AP3: 0 | AQ3: 0 | AR3: 0 | AS3: 0 | AT3: 0 | AU3: 0 | AV3: 0 | AW3: 0 | AX3: 34 | AY3: 0 | AZ3: 0 | BA3: 0 | BB3: 0 | BC3: 48 | BD3: 35 | BE3: 25 | BF3: 0 | BG3: 0 | BH3: 0 | BI3: 0 | BJ3: 0 | BK3: 21 | BL3: 0 | BM3: 54 | BN3: 6 | BO3: 0 | BP3: 0 | BQ3: 63 | BR3: 0 | BS3: 10 | BT3: 0 | BU3: 0 | BV3: 26 | BW3: 0 | BX3: 0 | BY3: 24 | BZ3: 0 | CA3: 0 | CB3: 0 | CC3: 0 | CD3: 0 | CE3: 0 | CF3: 0 | CG3: 0 | CH3: 0 | CI3: 0 | CJ3: 0 | CK3: 0 | CL3: 0 | CM3: 30 | CN3: 42 | CO3: 0 | CP3: 34 | CQ3: 43 | CR3: 0 | CS3: 0 | CT3: 0 | CU3: 0 | CV3: 15 | CW3: 0 | CX3: 0 | CY3: 46 | CZ3: 14 | DA3: 0 | DB3: 0 | DC3: 0 | DD3: 40 | DE3: 30 | DF3: 0 | DG3: 0 | DH3: 0 | DI3: 0 | DJ3: 0 | DK3: 13 | DL3: 0 | DM3: 14 | DN3: 0 | DO3: 32 | DP3: 21 | DQ3: 0 | DR3: 0 | DS3: 0 | DT3: 0 | DU3: 0 | DV3: 0 | DW3: 0 | DX3: 0 | DY3: 0 | DZ3: 0 | EA3: 15 | EB3: 0 | EC3: 0 | ED3: 17 | EE3: 0 | EF3: 0 | EG3: 15 | EH3: 0 | EI3: 0 | EJ3: 0 | EK3: 0 | EL3: 15 | EM3: 0 | EN3: 30 | EO3: 0 | EP3: 0 | EQ3: 47 | ER3: 0 | ES3: 0 | ET3: 55 | EU3: 37 | EV3: 0 | EW3: 0 | EX3: 27 | EY3: 0 | EZ3: 0 | FA3: 0 | FB3: 0 | FC3: 0 | FD3: 0 | FE3: 0 | FF3: 0 | FG3: 0 | FH3: 0 | FI3: 0 | FJ3: 10 | FK3: 0 | FL3: 0 | FM3: 0 | FN3: 0 | FO3: 0 | FP3: 16 | FQ3: 0 | FR3: 0 | FS3: 36 | FT3: 0 | FU3: 0 | FV3: 26 | FW3: 939 | FX3: 1019 | FY3: 924 | FZ3: 1210 | GA3: 1116 | GB3: 1019 | GC3: 169 | GD3: 164 | GE3: 277 | GF3: 241 | GG3: 123 | GH3: 114 | GI3: 105 | GJ3: 46 | GK3: 3 | GL3: 72 | GM3: 74 | GN3: 5 | GO3: 52 | GP3: 148 | GQ3: 96 | GR3: 36 | GS3: 92 | GT3: 58 | GU3: 282 | GV3: 38 | GW3: 289 | GX3: 74 | GY3: 93 | GZ3: 277 | HA3: 70 | HB3: 35 | HC3: 192 | HD3: 33 | HE3: 69 | HF3: 74 | HG3: 82 | HH3: 186 | HI3: 195 | HJ3: 34 | HK3: 116 | HL3: 94 | HM3: 45 | HN3: 140 | HO3: 141 | HP3: 191 | HQ3: 184 | HR3: 28 | HS3: 107 | HT3: 83 | HU3: 165 | HV3: 79 | HW3: 13 | HX3: 156 | HY3: 34 | HZ3: 130 | IA3: 58 | IB3: 193 | IC3: 15 | ID3: 72 | IE3: 126 | IF3: 0 | IG3: 79 | IH3: 97 | II3: 51 | IJ3: 145 | IK3: 92 | IL3: 55 | IM3: 132 | IN3: 145 | IO3: 261 | IP3: 44 | IQ3: 91 | IR3: 92 | IS3: 279 | IT3: 121 | IU3: 118 | IV3: 49 | IW3: 192 | IX3: 189 | IY3: 173 | IZ3: 161 | JA3: 81 | JB3: 48 | JC3: 115 | JD3: 42 | JE3: 78 | JF3: 21 | JG3: 114 | JH3: 214 | JI3: 234 | JJ3: 63 | JK3: 18 | JL3: 41 | JM3: 60 | JN3: 71 | JO3: 189 | JP3: 116 | JQ3: 168 | JR3: 221 | JS3: 83 | JT3: 316 | JU3: 530 | JV3: 465 | JW3: 456 | JX3: 536 | JY3: 471 | JZ3: 293 | KA3: 386 | KB3: 338 | KC3: 818 | KD3: 928 | KE3: 620 | KF3: 544 | KG3: 858 | KH3: 847 | KI3: 874 | KJ3: 648 | KK3: 1247 | KL3: 1297 | KM3: 1237 | KN3: 1408 | KO3: 1250 | KP3: 2161 | KR3: 667 | KS3: 824 | KT3: 954 | KU3: 709 | KV3: 366 | KW3: 894 | KX3: 892 | KY3: 670 | KZ3: 836 | LA3: 695 | LB3: 934 | LC3: 773 | LD3: 1261 | LE3: 1390 | LF3: 1886 | LG3: 1659 | LH3: 1428 | LI3: 1084 | LJ3: 1270 | LK3: 1457 | LL3: 1410 | LM3: 1718 | LN3: 1666 | LO3: 1642 | LP3: 350 | LQ3: 279 | LR3: 487 | LS3: 264 | LT3: 266 | LU3: 482 | LV3: 295 | LW3: 241 | LX3: 377 | LY3: 362 | LZ3: 388 | MA3: 492 | MB3: 407 | MC3: 404 | MD3: 436 | ME3: 306 | MF3: 172 | MG3: 295 | MH3: 345 | MI3: 258 | MJ3: 327 | MK3: 262 | ML3: 332 | MM3: 284 | MN3: 542 | MO3: 295 | MP3: 362 | MQ3: 0 | MR3: 508 | MS3: 234 | MT3: 342 | MU3: 263 | MV3: 303 | MW3: 314 | MX3: 226 | MY3: 216 | MZ3: 262 | NA3: 342 | NB3: 271 | NC3: 394 | ND3: 165 | NE3: 800 | NF3: 231 | NG3: 143 | NH3: 514 | NI3: 71 | NJ3: 406 | NK3: 446 | NL3: 571 | NM3: 154 | NN3: 323 | NO3: 273 | NP3: 735 | NQ3: 182 | NR3: 601 | NS3: 171 | NT3: 363 | NU3: 519 | NV3: 479 | NW3: 157 | NX3: 7406 | NY3: 203 | NZ3: 270 | OA3: 80 | OB3: 282 | OC3: 386 | OD3: 293 | OE3: 296 | OF3: 364 | OG3: 650 | OH3: 2224 | OI3: 1613 | OJ3: 1588 | OK3: 1596 | OL3: 2717 | OM3: 2548 | ON3: 2483 | OO3: 279 | OP3: 246 | OQ3: 878 | OR3: 177 | OS3: 703 | OT3: 678 | OU3: 83 | OV3: 285 | OW3: 586 | OX3: 607 | OY3: 122 | OZ3: 70 | PA3: 101 | PB3: 144 | PC3: 118 | PD3: 57 | PE3: 664 | PF3: 863 | PG3: 88 | PH3: 425 | PI3: 644 | PJ3: 480 | PK3: 505 | PL3: 134 | PM3: NA | PN3: 141 | PO3: NA | PP3: 584 | PQ3: 592 | PR3: 198 | PS3: NA | PT3: 116 | PU3: 110 | PV3: 71 | PW3: 194 | PX3: 552 | PY3: 70 | PZ3: 326 | QA3: 76 | QB3: 638 | QC3: 834 | QD3: 233 | QE3: 55 | QF3: 834 | QG3: 153 | QH3: 100 | QI3: 293 | QJ3: 263 | QK3: 50 | QL3: 830 | QM3: 388 | QN3: 266 | QO3: 300 | QP3: NA | QQ3: 296 | QR3: 249 | QS3: 251 | QT3: 279 | QU3: NA | QV3: 331 | QW3: 501 | QX3: 260 | QY3: 265 | QZ3: NA | RA3: 304 | RB3: 1295 | RC3: 1352 | RD3: 1597 | RE3: 1462 | RF3: 1388 | RG3: 1400 | RH3: 1470 | RI3: 1332 | RJ3: 1569 | RK3: 1640 | RM3: 1468 | RN3: 1551 | RO3: 1500 | RP3: 1535 | RQ3: 1460 | RR3: 1312 | RS3: 1516

Sheet Vehicle types
C2: Tonnage | D2: Length | E2: Loadability
B3: Tempo 2T 3W | C3: 2 | D3: 10
B4: Tempo 2T 4W | C4: 2 | D4: 10
B5: Canter 4T | C5: 4 | D5: 14 | E5: 0.45
B6: Canter 6.5T | C6: 6.5 | D6: 17 | E6: 0.6
B7: Canter 8.5T | C7: 8.5 | D7: 19 | E7: 0.7
B8: Truck 9T | C8: 9 | D8: 18 | E8: 1
B9: Container 14T | C9: 14 | D9: 32 | E9: 2
B10: Turbo 15T | C10: 15 | D10: 22 | E10: 1.25
B11: Tata 0.7T | C11: 0.7 | D11: 8 | E11: 0.1
